<?xml version="1.0"?>
<robot xmlns:xacro="http://www.ros.org/wiki/xacro">

    <link name="base_link">
        <visual>
            <geometry>
                <cylinder radius="0.475" length="0.547"/>
            </geometry>
            <origin xyz = "0 0 0.2735   " rpy="0 0 0"/>
            <material name="grey"/>
        </visual>
        <collision>
            <geometry>
                <box size="0.9605 0.9605 0.547"/>
            </geometry>
            <origin xyz = "0 0 0.2735" rpy="0 0 0"/>
        </collision>
    </link>

    <link name="link1">
        <visual>
            <geometry>
                <cylinder radius="0.465" length="1.72"/>
            </geometry>
            <origin xyz = "0 0 0.86" rpy="0 0 0"/>
            <material name="blue"/>
        </visual>   
        <collision>
            <geometry>
                <cylinder radius="0.465" length="1.72"/>
            </geometry>
            <origin xyz = "0 0 0.86" rpy="0 0 0"/>
        </collision>
    </link>

    <link name="link2">
        <visual>
            <geometry>
                <cylinder radius="0.465" length="3.5"/>
            </geometry>
            <origin xyz = "0 0 1.75" rpy="0 0 0"/>
            <material name="blue"/>
        </visual>  
        <collision>
            <geometry>
                <cylinder radius="0.465" length="3.5"/>
            </geometry>
            <origin xyz = "0 0 1.75" rpy="0 0 0"/>
        </collision> 
    </link>
   
    <link name="link3">
        <visual>
            <geometry>
                <cylinder radius="0.465" length="3.5"/>
            </geometry>
            <origin xyz = "0 0 1.75" rpy="0 0 0"/>
            <material name="blue"/>
        </visual>   
        <collision>
            <geometry>
                <cylinder radius="0.465" length="3.5"/>
            </geometry>
            <origin xyz = "0 0 1.75" rpy="0 0 0"/>
        </collision>
    </link>  

    <link name="link4"/>
        <!-- <visual>
            <geometry>
                <cylinder radius="0.0" length="0.0"/>
            </geometry>
            <origin xyz = "0 0 0.475" rpy="0 0 0"/>
            <material name="blue"/>
        </visual>
    </link> -->
`
    <link name="link5">
        <visual>
            <geometry>
                <cylinder radius="0.465" length="0.95"/>
            </geometry>
            <origin xyz = "0 0 -0.475" rpy="0 0 0"/>
            <material name="blue"/>
        </visual>
        <collision>
            <geometry>
                <cylinder radius="0.465" length="0.95"/>
            </geometry>
            <origin xyz = "0 0 -0.475" rpy="0 0 0"/>
        </collision>
    </link>

    <link name="link6">
        <visual>
            <geometry>
                <cylinder radius="0.36" length="0.8"/>
            </geometry>     
            <origin xyz = "0.1 0 0" rpy="0 1.57 0"/>
            <material name="blue"/>
        </visual>
        <collision>
            <geometry>
                <cylinder radius="0.36" length="0.8"/>
            </geometry>
            <origin xyz = "0.1 0 0" rpy="0 1.57 0"/>
        </collision>
    </link> 
    
    <link name="tool_link"/>

    <joint name="joint1" type="revolute">
        <parent link="base_link"/>
        <child link="link1"/>
        <origin xyz="0 0 0.547" rpy="0 0 -2.355"/>
        <axis xyz="0 0 1"/>
        <limit lower="0" upper="4.710" effort="1000.0" velocity="1.0"/>
    </joint>

    <joint name="joint2" type="revolute">
        <parent link="link1"/>
        <child link="link2"/>
        <origin xyz="0.9605 0 1.72" rpy="-2.355 0 0"/>
        <axis xyz="1 0 0"/>
        <limit lower="0" upper="4.710" effort="1000.0" velocity="1.0"/>
    </joint>

    <joint name="joint3" type="revolute">
        <parent link="link2"/>
        <child link="link3"/>
        <origin xyz="-0.9580 0 3.5" rpy="-2.355 0 0"/>
        <axis xyz="1 0 0"/>
        <limit lower="0" upper="4.710" effort="1000.0" velocity="1.0"/>
    </joint>

    <joint name="joint4" type="revolute">
        <parent link="link3"/>
        <child link="link4"/>
        <origin xyz="0.95 0 3.5" rpy="-2.355 0 0"/>
        <axis xyz="1 0 0"/>
        <limit lower="0" upper="4.710" effort="1000.0" velocity="1.0"/>
    </joint>

    <joint name="joint5" type="revolute">
        <parent link="link4"/>
        <child link="link5"/>
        <origin xyz="0 0 0.475" rpy="0 0 1.57"/>
        <axis xyz="0 0 -1"/>
        <limit lower="0" upper="3.14" effort="1000.0" velocity="1.0"/>
    </joint>

    <joint name="joint6" type="revolute">
        <parent link="link5"/>
        <child link="link6"/>
        <origin xyz="0 0 0.475" rpy="0 0 0"/>
        <axis xyz="1 0 0"/>
        <limit lower="0" upper="3.14" effort="1000.0" velocity="1.0"/>
    </joint>

    <joint name="hand_tool_joint" type="fixed">
        <parent link="link6"/>
        <child link="tool_link"/>
        <origin xyz="3.0 0 0" rpy="0 1.57 0"/>
    </joint>

</robot>